<?xml version="1.0" ?>

<!-- Copyright (C) 2023  Miguel Ángel González Santamarta

This program is free software: you can redistribute it and/or modify
it under the terms of the GNU General Public License as published by
the Free Software Foundation, either version 3 of the License, or
(at your option) any later version.

This program is distributed in the hope that it will be useful,
but WITHOUT ANY WARRANTY; without even the implied warranty of
MERCHANTABILITY or FITNESS FOR A PARTICULAR PURPOSE.  See the
GNU General Public License for more details.

You should have received a copy of the GNU General Public License
along with this program.  If not, see <https://www.gnu.org/licenses/>. -->

<robot name="corner" xmlns:xacro="http://www.ros.org/wiki/xacro">
    <xacro:property name="corner_box_length" value="0.43" />
    <xacro:property name="corner_box_width" value="0.29" />
    <xacro:property name="corner_box_depth" value="0.10" />
    <xacro:property name="corner_box_mass" value="0.25" />

    <xacro:include filename="$(find rover_description)/urdf/inertials.xacro"/>

    <!-- link -->
    <xacro:macro name="corner_link" params="lon_label lat_label reflect">
        <link name="${lon_label}_${lat_label}_corner_link">
            <visual>
                <origin rpy="0 0 0" xyz="0 0 0" />
                <geometry>
                    <mesh filename="package://rover_description/meshes/bases/${lon_label}_${lat_label}_steering_asm.stl" />
                    <!-- <box size="0.1 0.1 0.1"/> -->
                </geometry>
                <material name="white" />
            </visual>
            <collision>
                <origin rpy="0 0 0" xyz="0 0 0" />
                <geometry>
                    <mesh filename="package://rover_description/meshes/bases/${lon_label}_${lat_label}_steering_asm.stl" />
                    <!-- <box size="${corner_box_length} ${corner_box_width} ${corner_box_depth}"/> -->
                </geometry>
            </collision>
            <xacro:solid_cuboid_inertial 
                rpy="0 0 0" xyz="0 0 0"
                mass="${corner_box_mass}"
                x="${corner_box_length}" y="${corner_box_width}" z="${corner_box_depth}" />
        </link> 

        <gazebo reference="${lon_label}_${lat_label}_corner_link">
            <material>Gazebo/White</material>
        </gazebo>

    </xacro:macro>


    <!-- front joint -->
    <xacro:macro name="front_corner_joint" params="lat_label reflect">
        <joint name="front_${lat_label}_corner_joint" type="continuous">
            <origin rpy="0 0 0" xyz="0.2116 ${reflect * 0.075} -0.0279"/>
            <axis xyz="0 0 1" />
            <parent link="${lat_label}_rocker_link" />
            <child link="front_${lat_label}_corner_link" />
            <limit effort="1000.0" lower="-3.14159" upper="3.14159" velocity="30"/>
            <dynamics damping="0.0" friction="0.0"/>
        </joint>

        <gazebo reference="front_${lat_label}_corner_joint">
            <provideFeedback>true</provideFeedback>
        </gazebo>
    </xacro:macro>


    <!-- back joint -->
    <xacro:macro name="back_corner_joint" params="lat_label reflect">
        <joint name="back_${lat_label}_corner_joint" type="continuous">
            <origin rpy="0 0 0" xyz="-0.149 ${reflect * 0.05} 0.0338"/>
            <axis xyz="0 0 1" />
            <parent link="${lat_label}_bogie_link" />
            <child link="back_${lat_label}_corner_link" />
            <limit effort="1000.0" lower="-3.14159" upper="3.14159" velocity="30"/>
            <dynamics damping="0.0" friction="0.0"/>
        </joint>

        <gazebo reference="back_${lat_label}_corner_joint">
            <provideFeedback>true</provideFeedback>
        </gazebo>
    </xacro:macro>

</robot>