<?xml version="1.0" ?>

<!-- # MIT License

# Copyright (c) 2023  Miguel Ángel González Santamarta

# Permission is hereby granted, free of charge, to any person obtaining a copy
# of this software and associated documentation files (the "Software"), to deal
# in the Software without restriction, including without limitation the rights
# to use, copy, modify, merge, publish, distribute, sublicense, and/or sell
# copies of the Software, and to permit persons to whom the Software is
# furnished to do so, subject to the following conditions:

# The above copyright notice and this permission notice shall be included in all
# copies or substantial portions of the Software.

# THE SOFTWARE IS PROVIDED "AS IS", WITHOUT WARRANTY OF ANY KIND, EXPRESS OR
# IMPLIED, INCLUDING BUT NOT LIMITED TO THE WARRANTIES OF MERCHANTABILITY,
# FITNESS FOR A PARTICULAR PURPOSE AND NONINFRINGEMENT. IN NO EVENT SHALL THE
# AUTHORS OR COPYRIGHT HOLDERS BE LIABLE FOR ANY CLAIM, DAMAGES OR OTHER
# LIABILITY, WHETHER IN AN ACTION OF CONTRACT, TORT OR OTHERWISE, ARISING FROM,
# OUT OF OR IN CONNECTION WITH THE SOFTWARE OR THE USE OR OTHER DEALINGS IN THE
# SOFTWARE. -->

<robot xmlns:xacro="http://www.ros.org/wiki/xacro">
    <xacro:property name="rocker_box_length" value="0.43" />
    <xacro:property name="rocker_box_width" value="0.29" />
    <xacro:property name="rocker_box_depth" value="0.10" />
    <xacro:property name="rocker_box_mass" value="0.25" />

    <xacro:include filename="$(find rover_description)/urdf/inertials.xacro"/>


    <xacro:macro name="rocker" params="parent lat_label reflect">

        <!-- link -->
        <link name="${lat_label}_rocker_link">
            <visual>
                <origin rpy="0 0 0" xyz="0 0 0" />
                <geometry>
                    <mesh filename="package://rover_description/meshes/bases/${lat_label}_rocker_asm.stl" />
                    <!-- <box size="0.1 0.015 0.015"/> -->
                </geometry>
                <material name="white" />
            </visual>
            <collision>
                <origin rpy="0 0 0" xyz="0 0 0" />
                <geometry>
                    <!-- <mesh filename="package://rover_description/meshes/bases/${lat_label}_rocker_asm.stl" /> -->
                    <box size="${rocker_box_length} ${rocker_box_width} ${rocker_box_depth}"/>
                </geometry>
            </collision>
            <xacro:solid_cuboid_inertial 
                rpy="0 0 0" xyz="0 0 0"
                mass="${rocker_box_mass}"
                x="${rocker_box_length}" y="${rocker_box_width}" z="${rocker_box_depth}" />
        </link> 

        <gazebo reference="${lat_label}_rocker_link">
            <material>Gazebo/White</material>
        </gazebo>


        <!-- joint -->
        <joint name="${lat_label}_rocker_joint" type="continuous">
            <origin rpy="0 0 0" xyz="0.071 ${reflect * 0.155} 0.0118"/>
            <axis xyz="0 1 0" />
            <limit 
                lower="${-math_pi_over_4}"
                upper="${math_pi_over_4}"
                effort="100.0"
                velocity="30.0" />
            <parent link="${parent}" />
            <child link="${lat_label}_rocker_link" />
        </joint>

        <gazebo reference="${lat_label}_rocker_joint">
            <provideFeedback>true</provideFeedback>
            <implicitSpringDamper>true</implicitSpringDamper>
        </gazebo>
    </xacro:macro>
</robot>